try {
  let result = a;
} 
catch (err) {
  console.log(err);
}
finally {
  console.log("finally ");
}
